Workbook

Sheet Plant Head 17.08
A1: Year | B1: Total Employees | C1: I Level | D1: L Level | E1: U Level | F1: O Level | K1: U Level increase % | L1: O Level increase % | M1: U & O Level increase %
A2: 2023 | B2: =SUM(C2:F2) | C2: 318 | D2: 508 | E2: 327 | F2: 168 | K2: =E2/B2 | L2: =F2/B2 | M2: =L2+K2
A3: 2024 | B3: =SUM(C3:F3) | C3: 253 | D3: 412 | E3: 464 | F3: 192 | K3: =E3/B3 | L3: =F3/B3 | M3: =L3+K3
B4: year | C4: I Level | D4: L Level | E4: U Level | F4: O Level
B5: 2023 | C5: =C3/$B$3 | D5: 0.41 | E5: 0.25 | F5: =F3/$B$3 | G5: =SUM(C5:F5)
B6: 2024 | C6: 0.2 | D6: 0.25 | E6: 0.35 | F6: 0.2 | G6: =SUM(C6:F6)
A7: Plant Head data | B7: 2025 | C7: 0.093198992 | D7: 0.054575987 | E7: 0.46599496 | F7: 0.38623006 | G7: =SUM(C7:F7)

Sheet 2025-2026 comp
B2: Responsibility | C2: SECTION | D2: Head Count | E2: 2025 | I2: 2026 | N2: Gap
E3: I | F3: L | G3: U | H3: O | I3: I | J3: L | K3: U | L3: O | N3: I | O3: L | P3: U | Q3: O
B4: KUMAR | C4: MIXING | D4: =COUNTIFS('Name list'!$E:$E,'2025-2026 comp'!$C4) | E4: =COUNTIFS('Name list'!$I:$I,'2025-2026 comp'!E$3,'Name list'!$E:$E,'2025-2026 comp'!$C4) | F4: =COUNTIFS('Name list'!$I:$I,'2025-2026 comp'!F$3,'Name list'!$E:$E,'2025-2026 comp'!$C4) | G4: =COUNTIFS('Name list'!$I:$I,'2025-2026 comp'!G$3,'Name list'!$E:$E,'2025-2026 comp'!$C4) | H4: =COUNTIFS('Name list'!$I:$I,'2025-2026 comp'!H$3,'Name list'!$E:$E,'2025-2026 comp'!$C4) | I4: =COUNTIFS('Name list'!$Y:$Y,'2025-2026 comp'!I$3,'Name list'!$E:$E,'2025-2026 comp'!$C4) | J4: =COUNTIFS('Name list'!$Y:$Y,'2025-2026 comp'!J$3,'Name list'!$E:$E,'2025-2026 comp'!$C4) | K4: =COUNTIFS('Name list'!$Y:$Y,'2025-2026 comp'!K$3,'Name list'!$E:$E,'2025-2026 comp'!$C4) | L4: =COUNTIFS('Name list'!$Y:$Y,'2025-2026 comp'!L$3,'Name list'!$E:$E,'2025-2026 comp'!$C4) | N4: =I4-E4 | O4: =J4-F4 | P4: =K4-G4 | Q4: =L4-H4
B5: RAJESH | C5: TYRE CURING | D5: =COUNTIFS('Name list'!$E:$E,'2025-2026 comp'!$C5) | E5: =COUNTIFS('Name list'!$I:$I,'2025-2026 comp'!E$3,'Name list'!$E:$E,'2025-2026 comp'!$C5) | F5: =COUNTIFS('Name list'!$I:$I,'2025-2026 comp'!F$3,'Name list'!$E:$E,'2025-2026 comp'!$C5) | G5: =COUNTIFS('Name list'!$I:$I,'2025-2026 comp'!G$3,'Name list'!$E:$E,'2025-2026 comp'!$C5) | H5: =COUNTIFS('Name list'!$I:$I,'2025-2026 comp'!H$3,'Name list'!$E:$E,'2025-2026 comp'!$C5) | I5: =COUNTIFS('Name list'!$Y:$Y,'2025-2026 comp'!I$3,'Name list'!$E:$E,'2025-2026 comp'!$C5) | J5: =COUNTIFS('Name list'!$Y:$Y,'2025-2026 comp'!J$3,'Name list'!$E:$E,'2025-2026 comp'!$C5) | K5: =COUNTIFS('Name list'!$Y:$Y,'2025-2026 comp'!K$3,'Name list'!$E:$E,'2025-2026 comp'!$C5) | L5: =COUNTIFS('Name list'!$Y:$Y,'2025-2026 comp'!L$3,'Name list'!$E:$E,'2025-2026 comp'!$C5) | N5: =I5-E5 | O5: =J5-F5 | P5: =K5-G5 | Q5: =L5-H5
B6: ANBUNITHI | C6: SOLID TYRE | D6: =COUNTIFS('Name list'!$E:$E,'2025-2026 comp'!$C6) | E6: =COUNTIFS('Name list'!$I:$I,'2025-2026 comp'!E$3,'Name list'!$E:$E,'2025-2026 comp'!$C6) | F6: =COUNTIFS('Name list'!$I:$I,'2025-2026 comp'!F$3,'Name list'!$E:$E,'2025-2026 comp'!$C6) | G6: =COUNTIFS('Name list'!$I:$I,'2025-2026 comp'!G$3,'Name list'!$E:$E,'2025-2026 comp'!$C6) | H6: =COUNTIFS('Name list'!$I:$I,'2025-2026 comp'!H$3,'Name list'!$E:$E,'2025-2026 comp'!$C6) | I6: =COUNTIFS('Name list'!$Y:$Y,'2025-2026 comp'!I$3,'Name list'!$E:$E,'2025-2026 comp'!$C6) | J6: =COUNTIFS('Name list'!$Y:$Y,'2025-2026 comp'!J$3,'Name list'!$E:$E,'2025-2026 comp'!$C6) | K6: =COUNTIFS('Name list'!$Y:$Y,'2025-2026 comp'!K$3,'Name list'!$E:$E,'2025-2026 comp'!$C6) | L6: =COUNTIFS('Name list'!$Y:$Y,'2025-2026 comp'!L$3,'Name list'!$E:$E,'2025-2026 comp'!$C6) | N6: =I6-E6 | O6: =J6-F6 | P6: =K6-G6 | Q6: =L6-H6
B7: MANICKKAM | C7: EXTRUDER | D7: =COUNTIFS('Name list'!$E:$E,'2025-2026 comp'!$C7) | E7: =COUNTIFS('Name list'!$I:$I,'2025-2026 comp'!E$3,'Name list'!$E:$E,'2025-2026 comp'!$C7) | F7: =COUNTIFS('Name list'!$I:$I,'2025-2026 comp'!F$3,'Name list'!$E:$E,'2025-2026 comp'!$C7) | G7: =COUNTIFS('Name list'!$I:$I,'2025-2026 comp'!G$3,'Name list'!$E:$E,'2025-2026 comp'!$C7) | H7: =COUNTIFS('Name list'!$I:$I,'2025-2026 comp'!H$3,'Name list'!$E:$E,'2025-2026 comp'!$C7) | I7: =COUNTIFS('Name list'!$Y:$Y,'2025-2026 comp'!I$3,'Name list'!$E:$E,'2025-2026 comp'!$C7) | J7: =COUNTIFS('Name list'!$Y:$Y,'2025-2026 comp'!J$3,'Name list'!$E:$E,'2025-2026 comp'!$C7) | K7: =COUNTIFS('Name list'!$Y:$Y,'2025-2026 comp'!K$3,'Name list'!$E:$E,'2025-2026 comp'!$C7) | L7: =COUNTIFS('Name list'!$Y:$Y,'2025-2026 comp'!L$3,'Name list'!$E:$E,'2025-2026 comp'!$C7) | N7: =I7-E7 | O7: =J7-F7 | P7: =K7-G7 | Q7: =L7-H7
B8: MANICKKAM | C8: Extruder Cement Application | D8: =COUNTIFS('Name list'!$E:$E,'2025-2026 comp'!$C8) | E8: =COUNTIFS('Name list'!$I:$I,'2025-2026 comp'!E$3,'Name list'!$E:$E,'2025-2026 comp'!$C8) | F8: =COUNTIFS('Name list'!$I:$I,'2025-2026 comp'!F$3,'Name list'!$E:$E,'2025-2026 comp'!$C8) | G8: =COUNTIFS('Name list'!$I:$I,'2025-2026 comp'!G$3,'Name list'!$E:$E,'2025-2026 comp'!$C8) | H8: =COUNTIFS('Name list'!$I:$I,'2025-2026 comp'!H$3,'Name list'!$E:$E,'2025-2026 comp'!$C8) | I8: =COUNTIFS('Name list'!$Y:$Y,'2025-2026 comp'!I$3,'Name list'!$E:$E,'2025-2026 comp'!$C8) | J8: =COUNTIFS('Name list'!$Y:$Y,'2025-2026 comp'!J$3,'Name list'!$E:$E,'2025-2026 comp'!$C8) | K8: =COUNTIFS('Name list'!$Y:$Y,'2025-2026 comp'!K$3,'Name list'!$E:$E,'2025-2026 comp'!$C8) | L8: =COUNTIFS('Name list'!$Y:$Y,'2025-2026 comp'!L$3,'Name list'!$E:$E,'2025-2026 comp'!$C8) | N8: =I8-E8 | O8: =J8-F8 | P8: =K8-G8 | Q8: =L8-H8
B9: MANICKKAM | C9: STEELASTIC | D9: =COUNTIFS('Name list'!$E:$E,'2025-2026 comp'!$C9) | E9: =COUNTIFS('Name list'!$I:$I,'2025-2026 comp'!E$3,'Name list'!$E:$E,'2025-2026 comp'!$C9) | F9: =COUNTIFS('Name list'!$I:$I,'2025-2026 comp'!F$3,'Name list'!$E:$E,'2025-2026 comp'!$C9) | G9: =COUNTIFS('Name list'!$I:$I,'2025-2026 comp'!G$3,'Name list'!$E:$E,'2025-2026 comp'!$C9) | H9: =COUNTIFS('Name list'!$I:$I,'2025-2026 comp'!H$3,'Name list'!$E:$E,'2025-2026 comp'!$C9) | I9: =COUNTIFS('Name list'!$Y:$Y,'2025-2026 comp'!I$3,'Name list'!$E:$E,'2025-2026 comp'!$C9) | J9: =COUNTIFS('Name list'!$Y:$Y,'2025-2026 comp'!J$3,'Name list'!$E:$E,'2025-2026 comp'!$C9) | K9: =COUNTIFS('Name list'!$Y:$Y,'2025-2026 comp'!K$3,'Name list'!$E:$E,'2025-2026 comp'!$C9) | L9: =COUNTIFS('Name list'!$Y:$Y,'2025-2026 comp'!L$3,'Name list'!$E:$E,'2025-2026 comp'!$C9) | N9: =I9-E9 | O9: =J9-F9 | P9: =K9-G9 | Q9: =L9-H9
B10: SANKAR | C10: 3 ROLL-P2 | D10: =COUNTIFS('Name list'!$E:$E,'2025-2026 comp'!$C10) | E10: =COUNTIFS('Name list'!$I:$I,'2025-2026 comp'!E$3,'Name list'!$E:$E,'2025-2026 comp'!$C10) | F10: =COUNTIFS('Name list'!$I:$I,'2025-2026 comp'!F$3,'Name list'!$E:$E,'2025-2026 comp'!$C10) | G10: =COUNTIFS('Name list'!$I:$I,'2025-2026 comp'!G$3,'Name list'!$E:$E,'2025-2026 comp'!$C10) | H10: =COUNTIFS('Name list'!$I:$I,'2025-2026 comp'!H$3,'Name list'!$E:$E,'2025-2026 comp'!$C10) | I10: =COUNTIFS('Name list'!$Y:$Y,'2025-2026 comp'!I$3,'Name list'!$E:$E,'2025-2026 comp'!$C10) | J10: =COUNTIFS('Name list'!$Y:$Y,'2025-2026 comp'!J$3,'Name list'!$E:$E,'2025-2026 comp'!$C10) | K10: =COUNTIFS('Name list'!$Y:$Y,'2025-2026 comp'!K$3,'Name list'!$E:$E,'2025-2026 comp'!$C10) | L10: =COUNTIFS('Name list'!$Y:$Y,'2025-2026 comp'!L$3,'Name list'!$E:$E,'2025-2026 comp'!$C10) | N10: =I10-E10 | O10: =J10-F10 | P10: =K10-G10 | Q10: =L10-H10
B11: SANKAR | C11: 4 ROLL | D11: =COUNTIFS('Name list'!$E:$E,'2025-2026 comp'!$C11) | E11: =COUNTIFS('Name list'!$I:$I,'2025-2026 comp'!E$3,'Name list'!$E:$E,'2025-2026 comp'!$C11) | F11: =COUNTIFS('Name list'!$I:$I,'2025-2026 comp'!F$3,'Name list'!$E:$E,'2025-2026 comp'!$C11) | G11: =COUNTIFS('Name list'!$I:$I,'2025-2026 comp'!G$3,'Name list'!$E:$E,'2025-2026 comp'!$C11) | H11: =COUNTIFS('Name list'!$I:$I,'2025-2026 comp'!H$3,'Name list'!$E:$E,'2025-2026 comp'!$C11) | I11: =COUNTIFS('Name list'!$Y:$Y,'2025-2026 comp'!I$3,'Name list'!$E:$E,'2025-2026 comp'!$C11) | J11: =COUNTIFS('Name list'!$Y:$Y,'2025-2026 comp'!J$3,'Name list'!$E:$E,'2025-2026 comp'!$C11) | K11: =COUNTIFS('Name list'!$Y:$Y,'2025-2026 comp'!K$3,'Name list'!$E:$E,'2025-2026 comp'!$C11) | L11: =COUNTIFS('Name list'!$Y:$Y,'2025-2026 comp'!L$3,'Name list'!$E:$E,'2025-2026 comp'!$C11) | N11: =I11-E11 | O11: =J11-F11 | P11: =K11-G11 | Q11: =L11-H11
B12: SANKAR | C12: LINER DRESSING | D12: =COUNTIFS('Name list'!$E:$E,'2025-2026 comp'!$C12) | E12: =COUNTIFS('Name list'!$I:$I,'2025-2026 comp'!E$3,'Name list'!$E:$E,'2025-2026 comp'!$C12) | F12: =COUNTIFS('Name list'!$I:$I,'2025-2026 comp'!F$3,'Name list'!$E:$E,'2025-2026 comp'!$C12) | G12: =COUNTIFS('Name list'!$I:$I,'2025-2026 comp'!G$3,'Name list'!$E:$E,'2025-2026 comp'!$C12) | H12: =COUNTIFS('Name list'!$I:$I,'2025-2026 comp'!H$3,'Name list'!$E:$E,'2025-2026 comp'!$C12) | I12: =COUNTIFS('Name list'!$Y:$Y,'2025-2026 comp'!I$3,'Name list'!$E:$E,'2025-2026 comp'!$C12) | J12: =COUNTIFS('Name list'!$Y:$Y,'2025-2026 comp'!J$3,'Name list'!$E:$E,'2025-2026 comp'!$C12) | K12: =COUNTIFS('Name list'!$Y:$Y,'2025-2026 comp'!K$3,'Name list'!$E:$E,'2025-2026 comp'!$C12) | L12: =COUNTIFS('Name list'!$Y:$Y,'2025-2026 comp'!L$3,'Name list'!$E:$E,'2025-2026 comp'!$C12) | N12: =I12-E12 | O12: =J12-F12 | P12: =K12-G12 | Q12: =L12-H12
B13: SANKAR | C13: BEAD WINDING | D13: =COUNTIFS('Name list'!$E:$E,'2025-2026 comp'!$C13) | E13: =COUNTIFS('Name list'!$I:$I,'2025-2026 comp'!E$3,'Name list'!$E:$E,'2025-2026 comp'!$C13) | F13: =COUNTIFS('Name list'!$I:$I,'2025-2026 comp'!F$3,'Name list'!$E:$E,'2025-2026 comp'!$C13) | G13: =COUNTIFS('Name list'!$I:$I,'2025-2026 comp'!G$3,'Name list'!$E:$E,'2025-2026 comp'!$C13) | H13: =COUNTIFS('Name list'!$I:$I,'2025-2026 comp'!H$3,'Name list'!$E:$E,'2025-2026 comp'!$C13) | I13: =COUNTIFS('Name list'!$Y:$Y,'2025-2026 comp'!I$3,'Name list'!$E:$E,'2025-2026 comp'!$C13) | J13: =COUNTIFS('Name list'!$Y:$Y,'2025-2026 comp'!J$3,'Name list'!$E:$E,'2025-2026 comp'!$C13) | K13: =COUNTIFS('Name list'!$Y:$Y,'2025-2026 comp'!K$3,'Name list'!$E:$E,'2025-2026 comp'!$C13) | L13: =COUNTIFS('Name list'!$Y:$Y,'2025-2026 comp'!L$3,'Name list'!$E:$E,'2025-2026 comp'!$C13) | N13: =I13-E13 | O13: =J13-F13 | P13: =K13-G13 | Q13: =L13-H13
B14: SWAMINATHAN | C14: TYRE BUILDING-P1 | D14: =COUNTIFS('Name list'!$E:$E,'2025-2026 comp'!$C14) | E14: =COUNTIFS('Name list'!$I:$I,'2025-2026 comp'!E$3,'Name list'!$E:$E,'2025-2026 comp'!$C14) | F14: =COUNTIFS('Name list'!$I:$I,'2025-2026 comp'!F$3,'Name list'!$E:$E,'2025-2026 comp'!$C14) | G14: =COUNTIFS('Name list'!$I:$I,'2025-2026 comp'!G$3,'Name list'!$E:$E,'2025-2026 comp'!$C14) | H14: =COUNTIFS('Name list'!$I:$I,'2025-2026 comp'!H$3,'Name list'!$E:$E,'2025-2026 comp'!$C14) | I14: =COUNTIFS('Name list'!$Y:$Y,'2025-2026 comp'!I$3,'Name list'!$E:$E,'2025-2026 comp'!$C14) | J14: =COUNTIFS('Name list'!$Y:$Y,'2025-2026 comp'!J$3,'Name list'!$E:$E,'2025-2026 comp'!$C14) | K14: =COUNTIFS('Name list'!$Y:$Y,'2025-2026 comp'!K$3,'Name list'!$E:$E,'2025-2026 comp'!$C14) | L14: =COUNTIFS('Name list'!$Y:$Y,'2025-2026 comp'!L$3,'Name list'!$E:$E,'2025-2026 comp'!$C14) | N14: =I14-E14 | O14: =J14-F14 | P14: =K14-G14 | Q14: =L14-H14
B15: SWAMINATHAN | C15: BAND BUILDING-P1 | D15: =COUNTIFS('Name list'!$E:$E,'2025-2026 comp'!$C15) | E15: =COUNTIFS('Name list'!$I:$I,'2025-2026 comp'!E$3,'Name list'!$E:$E,'2025-2026 comp'!$C15) | F15: =COUNTIFS('Name list'!$I:$I,'2025-2026 comp'!F$3,'Name list'!$E:$E,'2025-2026 comp'!$C15) | G15: =COUNTIFS('Name list'!$I:$I,'2025-2026 comp'!G$3,'Name list'!$E:$E,'2025-2026 comp'!$C15) | H15: =COUNTIFS('Name list'!$I:$I,'2025-2026 comp'!H$3,'Name list'!$E:$E,'2025-2026 comp'!$C15) | I15: =COUNTIFS('Name list'!$Y:$Y,'2025-2026 comp'!I$3,'Name list'!$E:$E,'2025-2026 comp'!$C15) | J15: =COUNTIFS('Name list'!$Y:$Y,'2025-2026 comp'!J$3,'Name list'!$E:$E,'2025-2026 comp'!$C15) | K15: =COUNTIFS('Name list'!$Y:$Y,'2025-2026 comp'!K$3,'Name list'!$E:$E,'2025-2026 comp'!$C15) | L15: =COUNTIFS('Name list'!$Y:$Y,'2025-2026 comp'!L$3,'Name list'!$E:$E,'2025-2026 comp'!$C15) | N15: =I15-E15 | O15: =J15-F15 | P15: =K15-G15 | Q15: =L15-H15
... B37: FID QA Lead | C37: FID inspector QA | D37: =COUNTIFS('Name list'!$E:$E,'2025-2026 comp'!$C37) | E37: =COUNTIFS('Name list'!$I:$I,'2025-2026 comp'!E$3,'Name list'!$E:$E,'2025-2026 comp'!$C37) | F37: =COUNTIFS('Name list'!$I:$I,'2025-2026 comp'!F$3,'Name list'!$E:$E,'2025-2026 comp'!$C37) | G37: =COUNTIFS('Name list'!$I:$I,'2025-2026 comp'!G$3,'Name list'!$E:$E,'2025-2026 comp'!$C37) | H37: =COUNTIFS('Name list'!$I:$I,'2025-2026 comp'!H$3,'Name list'!$E:$E,'2025-2026 comp'!$C37) | I37: =COUNTIFS('Name list'!$Y:$Y,'2025-2026 comp'!I$3,'Name list'!$E:$E,'2025-2026 comp'!$C37) | J37: =COUNTIFS('Name list'!$Y:$Y,'2025-2026 comp'!J$3,'Name list'!$E:$E,'2025-2026 comp'!$C37) | K37: =COUNTIFS('Name list'!$Y:$Y,'2025-2026 comp'!K$3,'Name list'!$E:$E,'2025-2026 comp'!$C37) | L37: =COUNTIFS('Name list'!$Y:$Y,'2025-2026 comp'!L$3,'Name list'!$E:$E,'2025-2026 comp'!$C37) | N37: =I37-E37 | O37: =J37-F37 | P37: =K37-G37 | Q37: =L37-H37
C38: Grand Total | D38: =SUM(D4:D37) | E38: =SUM(E4:E37) | F38: =SUM(F4:F37) | G38: =SUM(G4:G37) | H38: =SUM(H4:H37) | I38: =SUM(I4:I37) | J38: =SUM(J4:J37) | K38: =SUM(K4:K37) | L38: =SUM(L4:L37)
E39: =E38/$D$38 | F39: =F38/$D$38 | G39: =G38/$D$38 | H39: =H38/$D$38 | I39: =I38/$D$38 | J39: =J38/$D$38 | K39: =K38/$D$38 | L39: =L38/$D$38
K40: =L39+K39

Sheet Abstract
B2: Responsibility | C2: SECTION | D2: Head Count | E2: 0 - 6 Days | F2: > 3 Months | G2: 2 Years | H2: > 4 Years | J2: Questionnaire Assessment | L2: Gemba evaluation | N2: Overall Assessment | P2: yet to receive
E3: I | F3: L | G3: U | H3: O | J3: Nos | K3: % | L3: Nos | M3: % | P3: Question | Q3: Gemba
B4: KUMAR | C4: MIXING | D4: =COUNTIFS('Name list'!$E:$E,Abstract!$C4) | E4: =COUNTIFS('Name list'!$Y:$Y,Abstract!E$3,'Name list'!$E:$E,Abstract!$C4) | F4: =COUNTIFS('Name list'!$Y:$Y,Abstract!F$3,'Name list'!$E:$E,Abstract!$C4) | G4: =COUNTIFS('Name list'!$Y:$Y,Abstract!G$3,'Name list'!$E:$E,Abstract!$C4) | H4: =COUNTIFS('Name list'!$Y:$Y,Abstract!H$3,'Name list'!$E:$E,Abstract!$C4) | J4: 97 | K4: =J4/D4 | L4: =COUNTIFS('Name list'!$E$3:$E$1048576,Abstract!$C4,'Name list'!$U$3:$U$1048576,">1") | M4: =L4/D4 | N4: =AVERAGE(K4,M4) | P4: 0 | Q4: =D4-L4
B5: RAJESH | C5: TYRE CURING | D5: =COUNTIFS('Name list'!$E:$E,Abstract!$C5) | E5: =COUNTIFS('Name list'!$Y:$Y,Abstract!E$3,'Name list'!$E:$E,Abstract!$C5) | F5: =COUNTIFS('Name list'!$Y:$Y,Abstract!F$3,'Name list'!$E:$E,Abstract!$C5) | G5: =COUNTIFS('Name list'!$Y:$Y,Abstract!G$3,'Name list'!$E:$E,Abstract!$C5) | H5: =COUNTIFS('Name list'!$Y:$Y,Abstract!H$3,'Name list'!$E:$E,Abstract!$C5) | J5: =COUNTIFS('Name list'!$E$3:$E$1048576,Abstract!$C5,'Name list'!$O$3:$O$1048576,">1") | K5: =J5/D5 | L5: =COUNTIFS('Name list'!$E$3:$E$1048576,Abstract!$C5,'Name list'!$U$3:$U$1048576,">1") | M5: =L5/D5 | N5: =AVERAGE(K5,M5) | P5: =D5-J5 | Q5: =D5-L5 | R5: =E5/$D$5 | S5: =F5/$D$5 | T5: =G5/$D$5 | U5: =H5/$D$5
B6: ANBUNITHI | C6: SOLID TYRE | D6: =COUNTIFS('Name list'!$E:$E,Abstract!$C6) | E6: =COUNTIFS('Name list'!$Y:$Y,Abstract!E$3,'Name list'!$E:$E,Abstract!$C6) | F6: =COUNTIFS('Name list'!$Y:$Y,Abstract!F$3,'Name list'!$E:$E,Abstract!$C6) | G6: =COUNTIFS('Name list'!$Y:$Y,Abstract!G$3,'Name list'!$E:$E,Abstract!$C6) | H6: =COUNTIFS('Name list'!$Y:$Y,Abstract!H$3,'Name list'!$E:$E,Abstract!$C6) | J6: =COUNTIFS('Name list'!$E$3:$E$1048576,Abstract!$C6,'Name list'!$O$3:$O$1048576,">1") | K6: =J6/D6 | L6: =COUNTIFS('Name list'!$E$3:$E$1048576,Abstract!$C6,'Name list'!$U$3:$U$1048576,">1") | M6: =L6/D6 | N6: =AVERAGE(K6,M6) | P6: =D6-J6 | Q6: =D6-L6
B7: MANICKKAM | C7: EXTRUDER | D7: =COUNTIFS('Name list'!$E:$E,Abstract!$C7) | E7: =COUNTIFS('Name list'!$Y:$Y,Abstract!E$3,'Name list'!$E:$E,Abstract!$C7) | F7: =COUNTIFS('Name list'!$Y:$Y,Abstract!F$3,'Name list'!$E:$E,Abstract!$C7) | G7: =COUNTIFS('Name list'!$Y:$Y,Abstract!G$3,'Name list'!$E:$E,Abstract!$C7) | H7: =COUNTIFS('Name list'!$Y:$Y,Abstract!H$3,'Name list'!$E:$E,Abstract!$C7) | J7: =COUNTIFS('Name list'!$E$3:$E$1048576,Abstract!$C7,'Name list'!$O$3:$O$1048576,">1") | K7: =J7/D7 | L7: =COUNTIFS('Name list'!$E$3:$E$1048576,Abstract!$C7,'Name list'!$U$3:$U$1048576,">1") | M7: =L7/D7 | N7: =AVERAGE(K7,M7) | P7: =D7-J7 | Q7: =D7-L7
B8: MANICKKAM | C8: STEELASTIC | D8: =COUNTIFS('Name list'!$E:$E,Abstract!$C8) | E8: =COUNTIFS('Name list'!$Y:$Y,Abstract!E$3,'Name list'!$E:$E,Abstract!$C8) | F8: =COUNTIFS('Name list'!$Y:$Y,Abstract!F$3,'Name list'!$E:$E,Abstract!$C8) | G8: =COUNTIFS('Name list'!$Y:$Y,Abstract!G$3,'Name list'!$E:$E,Abstract!$C8) | H8: =COUNTIFS('Name list'!$Y:$Y,Abstract!H$3,'Name list'!$E:$E,Abstract!$C8) | J8: =COUNTIFS('Name list'!$E$3:$E$1048576,Abstract!$C8,'Name list'!$O$3:$O$1048576,">1") | K8: =J8/D8 | L8: =COUNTIFS('Name list'!$E$3:$E$1048576,Abstract!$C8,'Name list'!$U$3:$U$1048576,">1") | M8: =L8/D8 | N8: =AVERAGE(K8,M8) | P8: =D8-J8 | Q8: =D8-L8
B9: SANKAR | C9: 3 ROLL-P2 | D9: =COUNTIFS('Name list'!$E:$E,Abstract!$C9) | E9: =COUNTIFS('Name list'!$Y:$Y,Abstract!E$3,'Name list'!$E:$E,Abstract!$C9) | F9: =COUNTIFS('Name list'!$Y:$Y,Abstract!F$3,'Name list'!$E:$E,Abstract!$C9) | G9: =COUNTIFS('Name list'!$Y:$Y,Abstract!G$3,'Name list'!$E:$E,Abstract!$C9) | H9: =COUNTIFS('Name list'!$Y:$Y,Abstract!H$3,'Name list'!$E:$E,Abstract!$C9) | J9: =COUNTIFS('Name list'!$E$3:$E$1048576,Abstract!$C9,'Name list'!$O$3:$O$1048576,">1") | K9: =J9/D9 | L9: =COUNTIFS('Name list'!$E$3:$E$1048576,Abstract!$C9,'Name list'!$U$3:$U$1048576,">1") | M9: =L9/D9 | N9: =AVERAGE(K9,M9) | P9: =D9-J9 | Q9: =D9-L9
B10: SANKAR | C10: 4 ROLL | D10: =COUNTIFS('Name list'!$E:$E,Abstract!$C10) | E10: =COUNTIFS('Name list'!$Y:$Y,Abstract!E$3,'Name list'!$E:$E,Abstract!$C10) | F10: =COUNTIFS('Name list'!$Y:$Y,Abstract!F$3,'Name list'!$E:$E,Abstract!$C10) | G10: =COUNTIFS('Name list'!$Y:$Y,Abstract!G$3,'Name list'!$E:$E,Abstract!$C10) | H10: =COUNTIFS('Name list'!$Y:$Y,Abstract!H$3,'Name list'!$E:$E,Abstract!$C10) | J10: =COUNTIFS('Name list'!$E$3:$E$1048576,Abstract!$C10,'Name list'!$O$3:$O$1048576,">1") | K10: =J10/D10 | L10: =COUNTIFS('Name list'!$E$3:$E$1048576,Abstract!$C10,'Name list'!$U$3:$U$1048576,">1") | M10: =L10/D10 | N10: =AVERAGE(K10,M10) | P10: =D10-J10 | Q10: =D10-L10
B11: SANKAR | C11: LINER DRESSING | D11: =COUNTIFS('Name list'!$E:$E,Abstract!$C11) | E11: =COUNTIFS('Name list'!$Y:$Y,Abstract!E$3,'Name list'!$E:$E,Abstract!$C11) | F11: =COUNTIFS('Name list'!$Y:$Y,Abstract!F$3,'Name list'!$E:$E,Abstract!$C11) | G11: =COUNTIFS('Name list'!$Y:$Y,Abstract!G$3,'Name list'!$E:$E,Abstract!$C11) | H11: =COUNTIFS('Name list'!$Y:$Y,Abstract!H$3,'Name list'!$E:$E,Abstract!$C11) | J11: =COUNTIFS('Name list'!$E$3:$E$1048576,Abstract!$C11,'Name list'!$O$3:$O$1048576,">1") | K11: =J11/D11 | L11: =COUNTIFS('Name list'!$E$3:$E$1048576,Abstract!$C11,'Name list'!$U$3:$U$1048576,">1") | M11: =L11/D11 | N11: =AVERAGE(K11,M11) | P11: =D11-J11 | Q11: =D11-L11
B12: SANKAR | C12: BEAD WINDING | D12: =COUNTIFS('Name list'!$E:$E,Abstract!$C12) | E12: =COUNTIFS('Name list'!$Y:$Y,Abstract!E$3,'Name list'!$E:$E,Abstract!$C12) | F12: =COUNTIFS('Name list'!$Y:$Y,Abstract!F$3,'Name list'!$E:$E,Abstract!$C12) | G12: =COUNTIFS('Name list'!$Y:$Y,Abstract!G$3,'Name list'!$E:$E,Abstract!$C12) | H12: =COUNTIFS('Name list'!$Y:$Y,Abstract!H$3,'Name list'!$E:$E,Abstract!$C12) | J12: =COUNTIFS('Name list'!$E$3:$E$1048576,Abstract!$C12,'Name list'!$O$3:$O$1048576,">1") | K12: =J12/D12 | L12: =COUNTIFS('Name list'!$E$3:$E$1048576,Abstract!$C12,'Name list'!$U$3:$U$1048576,">1") | M12: =L12/D12 | N12: =AVERAGE(K12,M12) | P12: =D12-J12 | Q12: =D12-L12
B13: SWAMINATHAN | C13: TYRE BUILDING-P1 | D13: =COUNTIFS('Name list'!$E:$E,Abstract!$C13) | E13: =COUNTIFS('Name list'!$Y:$Y,Abstract!E$3,'Name list'!$E:$E,Abstract!$C13) | F13: =COUNTIFS('Name list'!$Y:$Y,Abstract!F$3,'Name list'!$E:$E,Abstract!$C13) | G13: =COUNTIFS('Name list'!$Y:$Y,Abstract!G$3,'Name list'!$E:$E,Abstract!$C13) | H13: =COUNTIFS('Name list'!$Y:$Y,Abstract!H$3,'Name list'!$E:$E,Abstract!$C13) | J13: =COUNTIFS('Name list'!$E$3:$E$1048576,Abstract!$C13,'Name list'!$O$3:$O$1048576,">1") | K13: =J13/D13 | L13: =COUNTIFS('Name list'!$E$3:$E$1048576,Abstract!$C13,'Name list'!$U$3:$U$1048576,">1") | M13: =L13/D13 | N13: =AVERAGE(K13,M13) | P13: =D13-J13 | Q13: =D13-L13
B14: SWAMINATHAN | C14: BAND BUILDING-P1 | D14: =COUNTIFS('Name list'!$E:$E,Abstract!$C14) | E14: =COUNTIFS('Name list'!$Y:$Y,Abstract!E$3,'Name list'!$E:$E,Abstract!$C14) | F14: =COUNTIFS('Name list'!$Y:$Y,Abstract!F$3,'Name list'!$E:$E,Abstract!$C14) | G14: =COUNTIFS('Name list'!$Y:$Y,Abstract!G$3,'Name list'!$E:$E,Abstract!$C14) | H14: =COUNTIFS('Name list'!$Y:$Y,Abstract!H$3,'Name list'!$E:$E,Abstract!$C14) | J14: =COUNTIFS('Name list'!$E$3:$E$1048576,Abstract!$C14,'Name list'!$O$3:$O$1048576,">1") | K14: =J14/D14 | L14: =COUNTIFS('Name list'!$E$3:$E$1048576,Abstract!$C14,'Name list'!$U$3:$U$1048576,">1") | M14: =L14/D14 | N14: =AVERAGE(K14,M14) | P14: =D14-J14 | Q14: =D14-L14
B15: SWAMINATHAN | C15: BIAS CUTTING-2 | D15: =COUNTIFS('Name list'!$E:$E,Abstract!$C15) | E15: =COUNTIFS('Name list'!$Y:$Y,Abstract!E$3,'Name list'!$E:$E,Abstract!$C15) | F15: =COUNTIFS('Name list'!$Y:$Y,Abstract!F$3,'Name list'!$E:$E,Abstract!$C15) | G15: =COUNTIFS('Name list'!$Y:$Y,Abstract!G$3,'Name list'!$E:$E,Abstract!$C15) | H15: =COUNTIFS('Name list'!$Y:$Y,Abstract!H$3,'Name list'!$E:$E,Abstract!$C15) | J15: =COUNTIFS('Name list'!$E$3:$E$1048576,Abstract!$C15,'Name list'!$O$3:$O$1048576,">1") | K15: =J15/D15 | L15: =COUNTIFS('Name list'!$E$3:$E$1048576,Abstract!$C15,'Name list'!$U$3:$U$1048576,">1") | M15: =L15/D15 | N15: =AVERAGE(K15,M15) | P15: =D15-J15 | Q15: =D15-L15
B16: SWAMINATHAN | C16: RADIAL MARANGONI | D16: =COUNTIFS('Name list'!$E:$E,Abstract!$C16) | E16: =COUNTIFS('Name list'!$Y:$Y,Abstract!E$3,'Name list'!$E:$E,Abstract!$C16) | F16: =COUNTIFS('Name list'!$Y:$Y,Abstract!F$3,'Name list'!$E:$E,Abstract!$C16) | G16: =COUNTIFS('Name list'!$Y:$Y,Abstract!G$3,'Name list'!$E:$E,Abstract!$C16) | H16: =COUNTIFS('Name list'!$Y:$Y,Abstract!H$3,'Name list'!$E:$E,Abstract!$C16) | J16: =COUNTIFS('Name list'!$E$3:$E$1048576,Abstract!$C16,'Name list'!$O$3:$O$1048576,">1") | K16: =J16/D16 | L16: =COUNTIFS('Name list'!$E$3:$E$1048576,Abstract!$C16,'Name list'!$U$3:$U$1048576,">1") | M16: =L16/D16 | N16: =AVERAGE(K16,M16) | P16: =D16-J16 | Q16: =D16-L16
B17: SWAMINATHAN | C17: SLITTING | D17: =COUNTIFS('Name list'!$E:$E,Abstract!$C17) | E17: =COUNTIFS('Name list'!$Y:$Y,Abstract!E$3,'Name list'!$E:$E,Abstract!$C17) | F17: =COUNTIFS('Name list'!$Y:$Y,Abstract!F$3,'Name list'!$E:$E,Abstract!$C17) | G17: =COUNTIFS('Name list'!$Y:$Y,Abstract!G$3,'Name list'!$E:$E,Abstract!$C17) | H17: =COUNTIFS('Name list'!$Y:$Y,Abstract!H$3,'Name list'!$E:$E,Abstract!$C17) | J17: =COUNTIFS('Name list'!$E$3:$E$1048576,Abstract!$C17,'Name list'!$O$3:$O$1048576,">1") | K17: =J17/D17 | L17: =COUNTIFS('Name list'!$E$3:$E$1048576,Abstract!$C17,'Name list'!$U$3:$U$1048576,">1") | M17: =L17/D17 | N17: =AVERAGE(K17,M17) | P17: =D17-J17 | Q17: =D17-L17
... B36: FID QA Lead | C36: FID inspector QA | D36: =COUNTIFS('Name list'!$E:$E,Abstract!$C36) | E36: =COUNTIFS('Name list'!$Y:$Y,Abstract!E$3,'Name list'!$E:$E,Abstract!$C36) | F36: =COUNTIFS('Name list'!$Y:$Y,Abstract!F$3,'Name list'!$E:$E,Abstract!$C36) | G36: =COUNTIFS('Name list'!$Y:$Y,Abstract!G$3,'Name list'!$E:$E,Abstract!$C36) | H36: =COUNTIFS('Name list'!$Y:$Y,Abstract!H$3,'Name list'!$E:$E,Abstract!$C36) | J36: =COUNTIFS('Name list'!$E$3:$E$1048576,Abstract!$C36,'Name list'!$O$3:$O$1048576,">1") | K36: =J36/D36 | L36: =COUNTIFS('Name list'!$E$3:$E$1048576,Abstract!$C36,'Name list'!$U$3:$U$1048576,">1") | M36: =L36/D36 | N36: =AVERAGE(K36,M36) | P36: =D36-J36 | Q36: =D36-L36
C37: Grand Total | D37: =SUM(D4:D36) | E37: =SUM(E4:E36) | F37: =SUM(F4:F36) | G37: =SUM(G4:G36) | H37: =SUM(H4:H36) | J37: =SUM(J4:J36) | K37: =AVERAGE(K4:K36) | L37: =SUM(L4:L36) | M37: =AVERAGE(M4:M36) | N37: =AVERAGE(N4:N36) | P37: =SUM(P4:P36) | Q37: =SUM(Q4:Q36)
E38: =E37/$D$37 | F38: =F37/$D$37 | G38: =G37/$D$37 | H38: =H37/$D$37
G39: =H38+G38

Sheet Name list
J1: Quest | S1: Gemba
B2: EMP NO | C2: NAME | D2: DEPT | E2: SECTION | F2: DOJ | G2: Exp | H2: Eligible skill level | I2: Current skill level 2025 | J2: Safety | K2: Process | L2: Quality | M2: CI & TPM | N2: System | O2: Knowledge Mark | P2: Knowledge % | Q2: Result | S2: Safety/ 5S | T2: SOP's/ WI CHECK | U2: Skill Assessment Mark | V2: Skill Assessment % | W2: Result | X2: Overall Result | Y2: After evaluation Skill level | Z2: recheck
A3: =ROW()-2 | B3: 900118 | C3: AROCKIA SAMY A | D3: PRODUCTION | E3: 4 ROLL | F3: 40634 | G3: =NOW()-F3 | H3: O | I3: O | J3: 9 | K3: 7 | L3: 4 | M3: 8 | O3: =SUM(J3:N3) | P3: =O3/IF(H3="L",20,IF(H3="U",30,IF(H3="O",40,IF(H3="I",20,"")))) | Q3: =IF(AND(H3="L", P3>=50%), "Pass", IF(AND(H3="U", P3>=60%), "Pass", IF(AND(H3="O", P3>=75%), "Pass", "Fail"))) | S3: 16 | T3: 12 | U3: =SUM(S3:T3) | V3: =U3/IF(H3="L",35,IF(H3="U",35,IF(H3="O",35,IF(H3="I",35,"")))) | W3: =IF(AND(H3="L", V3>=50%), "Pass", IF(AND(H3="U", V3>=60%), "Pass", IF(AND(H3="O", V3>=75%), "Pass", "Fail"))) | X3: =IF(AND(Q3="Pass", W3="Pass"), "Pass", "Fail") | Y3: =IF($X3="Pass",$H3, IF(H3="L","I", IF(H3="U","L", IF(H3="O","U", "I"))))
A4: =ROW()-2 | B4: 901128 | C4: MURUGAN M | D4: PRODUCTION | E4: MIXING | F4: 40260 | G4: =NOW()-F4 | H4: O | I4: U | J4: NIL | P4: =O4/IF(H4="L",20,IF(H4="U",30,IF(H4="O",40,IF(H4="I",20,"")))) | Q4: =IF(AND(H4="L", P4>=50%), "Pass", IF(AND(H4="U", P4>=60%), "Pass", IF(AND(H4="O", P4>=75%), "Pass", "Fail"))) | S4: 12 | T4: 10 | U4: =SUM(S4:T4) | V4: =U4/IF(H4="L",35,IF(H4="U",35,IF(H4="O",35,IF(H4="I",35,"")))) | W4: =IF(AND(H4="L", V4>=50%), "Pass", IF(AND(H4="U", V4>=60%), "Pass", IF(AND(H4="O", V4>=75%), "Pass", "Fail"))) | X4: =IF(AND(Q4="Pass", W4="Pass"), "Pass", "Fail") | Y4: =IF($X4="Pass",$H4, IF(H4="L","I", IF(H4="U","L", IF(H4="O","U", "I"))))
A5: =ROW()-2 | B5: SK1673 | C5: PANDARAM S | D5: PRODUCTION | E5: TYRE BUILDING-P1 | F5: 40496 | G5: =NOW()-F5 | H5: O | I5: U | J5: 10 | K5: 9 | L5: 9 | M5: 6 | O5: =SUM(J5:N5) | P5: =O5/IF(H5="L",20,IF(H5="U",30,IF(H5="O",40,IF(H5="I",20,"")))) | Q5: =IF(AND(H5="L", P5>=50%), "Pass", IF(AND(H5="U", P5>=60%), "Pass", IF(AND(H5="O", P5>=75%), "Pass", "Fail"))) | S5: 14 | T5: 15 | U5: =SUM(S5:T5) | V5: =U5/IF(H5="L",35,IF(H5="U",35,IF(H5="O",35,IF(H5="I",35,"")))) | W5: =IF(AND(H5="L", V5>=50%), "Pass", IF(AND(H5="U", V5>=60%), "Pass", IF(AND(H5="O", V5>=75%), "Pass", "Fail"))) | X5: =IF(AND(Q5="Pass", W5="Pass"), "Pass", "Fail") | Y5: =IF($X5="Pass",$H5, IF(H5="L","I", IF(H5="U","L", IF(H5="O","U", "I"))))
A6: =ROW()-2 | B6: 900742 | C6: SELVARAJ S | D6: PRODUCTION | E6: MIXING | F6: 40610 | G6: =NOW()-F6 | H6: O | I6: U | J6: NIL | P6: =O6/IF(H6="L",20,IF(H6="U",30,IF(H6="O",40,IF(H6="I",20,"")))) | Q6: =IF(AND(H6="L", P6>=50%), "Pass", IF(AND(H6="U", P6>=60%), "Pass", IF(AND(H6="O", P6>=75%), "Pass", "Fail"))) | S6: 13 | T6: 12 | U6: =SUM(S6:T6) | V6: =U6/IF(H6="L",35,IF(H6="U",35,IF(H6="O",35,IF(H6="I",35,"")))) | W6: =IF(AND(H6="L", V6>=50%), "Pass", IF(AND(H6="U", V6>=60%), "Pass", IF(AND(H6="O", V6>=75%), "Pass", "Fail"))) | X6: =IF(AND(Q6="Pass", W6="Pass"), "Pass", "Fail") | Y6: =IF($X6="Pass",$H6, IF(H6="L","I", IF(H6="U","L", IF(H6="O","U", "I"))))
A7: =ROW()-2 | B7: 900119 | C7: CHINNA DURAI S | D7: PRODUCTION | E7: 4 ROLL | F7: 40634 | G7: =NOW()-F7 | H7: O | I7: O | J7: 9 | K7: 8 | L7: 7 | M7: 7 | O7: =SUM(J7:N7) | P7: =O7/IF(H7="L",20,IF(H7="U",30,IF(H7="O",40,IF(H7="I",20,"")))) | Q7: =IF(AND(H7="L", P7>=50%), "Pass", IF(AND(H7="U", P7>=60%), "Pass", IF(AND(H7="O", P7>=75%), "Pass", "Fail"))) | S7: 16 | T7: 12 | U7: =SUM(S7:T7) | V7: =U7/IF(H7="L",35,IF(H7="U",35,IF(H7="O",35,IF(H7="I",35,"")))) | W7: =IF(AND(H7="L", V7>=50%), "Pass", IF(AND(H7="U", V7>=60%), "Pass", IF(AND(H7="O", V7>=75%), "Pass", "Fail"))) | X7: =IF(AND(Q7="Pass", W7="Pass"), "Pass", "Fail") | Y7: =IF($X7="Pass",$H7, IF(H7="L","I", IF(H7="U","L", IF(H7="O","U", "I"))))
A8: =ROW()-2 | B8: 900120 | C8: SANKARA PANDIAN S | D8: PRODUCTION | E8: 4 ROLL | F8: 40634 | G8: =NOW()-F8 | H8: O | I8: O | J8: 9 | K8: 7 | L8: 8 | M8: 8 | O8: =SUM(J8:N8) | P8: =O8/IF(H8="L",20,IF(H8="U",30,IF(H8="O",40,IF(H8="I",20,"")))) | Q8: =IF(AND(H8="L", P8>=50%), "Pass", IF(AND(H8="U", P8>=60%), "Pass", IF(AND(H8="O", P8>=75%), "Pass", "Fail"))) | S8: 14 | T8: 8 | U8: =SUM(S8:T8) | V8: =U8/IF(H8="L",35,IF(H8="U",35,IF(H8="O",35,IF(H8="I",35,"")))) | W8: =IF(AND(H8="L", V8>=50%), "Pass", IF(AND(H8="U", V8>=60%), "Pass", IF(AND(H8="O", V8>=75%), "Pass", "Fail"))) | X8: =IF(AND(Q8="Pass", W8="Pass"), "Pass", "Fail") | Y8: =IF($X8="Pass",$H8, IF(H8="L","I", IF(H8="U","L", IF(H8="O","U", "I"))))
A9: =ROW()-2 | B9: 900121 | C9: SUNIL KUMAR SINGH | D9: PRODUCTION | E9: 3 ROLL-P2 | F9: 40634 | G9: =NOW()-F9 | H9: O | I9: U | J9: 6 | K9: 7 | L9: 5 | M9: 7 | O9: =SUM(J9:N9) | P9: =O9/IF(H9="L",20,IF(H9="U",30,IF(H9="O",40,IF(H9="I",20,"")))) | Q9: =IF(AND(H9="L", P9>=50%), "Pass", IF(AND(H9="U", P9>=60%), "Pass", IF(AND(H9="O", P9>=75%), "Pass", "Fail"))) | S9: 15 | T9: 11 | U9: =SUM(S9:T9) | V9: =U9/IF(H9="L",35,IF(H9="U",35,IF(H9="O",35,IF(H9="I",35,"")))) | W9: =IF(AND(H9="L", V9>=50%), "Pass", IF(AND(H9="U", V9>=60%), "Pass", IF(AND(H9="O", V9>=75%), "Pass", "Fail"))) | X9: =IF(AND(Q9="Pass", W9="Pass"), "Pass", "Fail") | Y9: =IF($X9="Pass",$H9, IF(H9="L","I", IF(H9="U","L", IF(H9="O","U", "I"))))
A10: =ROW()-2 | B10: 900122 | C10: MUTHUKUTTI A | D10: PRODUCTION | E10: 4 ROLL | F10: 40634 | G10: =NOW()-F10 | H10: O | I10: U | J10: 9 | K10: 7 | L10: 7 | M10: 8 | O10: =SUM(J10:N10) | P10: =O10/IF(H10="L",20,IF(H10="U",30,IF(H10="O",40,IF(H10="I",20,"")))) | Q10: =IF(AND(H10="L", P10>=50%), "Pass", IF(AND(H10="U", P10>=60%), "Pass", IF(AND(H10="O", P10>=75%), "Pass", "Fail"))) | S10: 13 | T10: 6 | U10: =SUM(S10:T10) | V10: =U10/IF(H10="L",35,IF(H10="U",35,IF(H10="O",35,IF(H10="I",35,"")))) | W10: =IF(AND(H10="L", V10>=50%), "Pass", IF(AND(H10="U", V10>=60%), "Pass", IF(AND(H10="O", V10>=75%), "Pass", "Fail"))) | X10: =IF(AND(Q10="Pass", W10="Pass"), "Pass", "Fail") | Y10: =IF($X10="Pass",$H10, IF(H10="L","I", IF(H10="U","L", IF(H10="O","U", "I"))))
A11: =ROW()-2 | B11: 900123 | C11: THEVENDIRAN N | D11: PRODUCTION | E11: BAND BUILDING-P1 | F11: 40634 | G11: =NOW()-F11 | H11: O | I11: U | J11: 10 | K11: 8 | L11: 9 | M11: 8 | O11: =SUM(J11:N11) | P11: =O11/IF(H11="L",20,IF(H11="U",30,IF(H11="O",40,IF(H11="I",20,"")))) | Q11: =IF(AND(H11="L", P11>=50%), "Pass", IF(AND(H11="U", P11>=60%), "Pass", IF(AND(H11="O", P11>=75%), "Pass", "Fail"))) | S11: 20 | T11: 15 | U11: =SUM(S11:T11) | V11: =U11/IF(H11="L",35,IF(H11="U",35,IF(H11="O",35,IF(H11="I",35,"")))) | W11: =IF(AND(H11="L", V11>=50%), "Pass", IF(AND(H11="U", V11>=60%), "Pass", IF(AND(H11="O", V11>=75%), "Pass", "Fail"))) | X11: =IF(AND(Q11="Pass", W11="Pass"), "Pass", "Fail") | Y11: =IF($X11="Pass",$H11, IF(H11="L","I", IF(H11="U","L", IF(H11="O","U", "I"))))
A12: =ROW()-2 | B12: 900126 | C12: ATUL KUMAR SINGH | D12: PRODUCTION | E12: BEAD WINDING | F12: 40634 | G12: =NOW()-F12 | H12: O | I12: U | J12: 8 | K12: 6 | L12: 2 | M12: 5 | O12: =SUM(J12:N12) | P12: =O12/IF(H12="L",20,IF(H12="U",30,IF(H12="O",40,IF(H12="I",20,"")))) | Q12: =IF(AND(H12="L", P12>=50%), "Pass", IF(AND(H12="U", P12>=60%), "Pass", IF(AND(H12="O", P12>=75%), "Pass", "Fail"))) | S12: 15 | T12: 11 | U12: =SUM(S12:T12) | V12: =U12/IF(H12="L",35,IF(H12="U",35,IF(H12="O",35,IF(H12="I",35,"")))) | W12: =IF(AND(H12="L", V12>=50%), "Pass", IF(AND(H12="U", V12>=60%), "Pass", IF(AND(H12="O", V12>=75%), "Pass", "Fail"))) | X12: =IF(AND(Q12="Pass", W12="Pass"), "Pass", "Fail") | Y12: =IF($X12="Pass",$H12, IF(H12="L","I", IF(H12="U","L", IF(H12="O","U", "I"))))
A13: =ROW()-2 | B13: 900127 | C13: RAJA S | D13: PRODUCTION | E13: BEAD WINDING | F13: 40634 | G13: =NOW()-F13 | H13: O | I13: O | J13: 9 | K13: 7 | L13: 4 | M13: 4 | O13: =SUM(J13:N13) | P13: =O13/IF(H13="L",20,IF(H13="U",30,IF(H13="O",40,IF(H13="I",20,"")))) | Q13: =IF(AND(H13="L", P13>=50%), "Pass", IF(AND(H13="U", P13>=60%), "Pass", IF(AND(H13="O", P13>=75%), "Pass", "Fail"))) | S13: 16 | T13: 8 | U13: =SUM(S13:T13) | V13: =U13/IF(H13="L",35,IF(H13="U",35,IF(H13="O",35,IF(H13="I",35,"")))) | W13: =IF(AND(H13="L", V13>=50%), "Pass", IF(AND(H13="U", V13>=60%), "Pass", IF(AND(H13="O", V13>=75%), "Pass", "Fail"))) | X13: =IF(AND(Q13="Pass", W13="Pass"), "Pass", "Fail") | Y13: =IF($X13="Pass",$H13, IF(H13="L","I", IF(H13="U","L", IF(H13="O","U", "I"))))
A14: =ROW()-2 | B14: 900128 | C14: DABLU KUMAR | D14: PRODUCTION | E14: BEAD WINDING | F14: 40634 | G14: =NOW()-F14 | H14: O | I14: U | J14: 7 | K14: 9 | L14: 7 | M14: 8 | O14: =SUM(J14:N14) | P14: =O14/IF(H14="L",20,IF(H14="U",30,IF(H14="O",40,IF(H14="I",20,"")))) | Q14: =IF(AND(H14="L", P14>=50%), "Pass", IF(AND(H14="U", P14>=60%), "Pass", IF(AND(H14="O", P14>=75%), "Pass", "Fail"))) | S14: 16 | T14: 12 | U14: =SUM(S14:T14) | V14: =U14/IF(H14="L",35,IF(H14="U",35,IF(H14="O",35,IF(H14="I",35,"")))) | W14: =IF(AND(H14="L", V14>=50%), "Pass", IF(AND(H14="U", V14>=60%), "Pass", IF(AND(H14="O", V14>=75%), "Pass", "Fail"))) | X14: =IF(AND(Q14="Pass", W14="Pass"), "Pass", "Fail") | Y14: =IF($X14="Pass",$H14, IF(H14="L","I", IF(H14="U","L", IF(H14="O","U", "I"))))
A15: =ROW()-2 | B15: 900129 | C15: THANGA MUTHU S | D15: PRODUCTION | E15: BIAS CUTTING-4 | F15: 40634 | G15: =NOW()-F15 | H15: O | I15: O | J15: 9 | K15: 4 | L15: 5 | M15: 5 | O15: =SUM(J15:N15) | P15: =O15/IF(H15="L",20,IF(H15="U",30,IF(H15="O",40,IF(H15="I",20,"")))) | Q15: =IF(AND(H15="L", P15>=50%), "Pass", IF(AND(H15="U", P15>=60%), "Pass", IF(AND(H15="O", P15>=75%), "Pass", "Fail"))) | S15: 18 | T15: 15 | U15: =SUM(S15:T15) | V15: =U15/IF(H15="L",35,IF(H15="U",35,IF(H15="O",35,IF(H15="I",35,"")))) | W15: =IF(AND(H15="L", V15>=50%), "Pass", IF(AND(H15="U", V15>=60%), "Pass", IF(AND(H15="O", V15>=75%), "Pass", "Fail"))) | X15: =IF(AND(Q15="Pass", W15="Pass"), "Pass", "Fail") | Y15: =IF($X15="Pass",$H15, IF(H15="L","I", IF(H15="U","L", IF(H15="O","U", "I"))))
A16: =ROW()-2 | B16: 900130 | C16: SANKAR E | D16: PRODUCTION | E16: BIAS CUTTING-2 | F16: 40634 | G16: =NOW()-F16 | H16: O | I16: O | J16: 10 | K16: 9 | L16: 1 | M16: 8 | O16: =SUM(J16:N16) | P16: =O16/IF(H16="L",20,IF(H16="U",30,IF(H16="O",40,IF(H16="I",20,"")))) | Q16: =IF(AND(H16="L", P16>=50%), "Pass", IF(AND(H16="U", P16>=60%), "Pass", IF(AND(H16="O", P16>=75%), "Pass", "Fail"))) | S16: 19 | T16: 13 | U16: =SUM(S16:T16) | V16: =U16/IF(H16="L",35,IF(H16="U",35,IF(H16="O",35,IF(H16="I",35,"")))) | W16: =IF(AND(H16="L", V16>=50%), "Pass", IF(AND(H16="U", V16>=60%), "Pass", IF(AND(H16="O", V16>=75%), "Pass", "Fail"))) | X16: =IF(AND(Q16="Pass", W16="Pass"), "Pass", "Fail") | Y16: =IF($X16="Pass",$H16, IF(H16="L","I", IF(H16="U","L", IF(H16="O","U", "I"))))
A17: =ROW()-2 | B17: 900131 | C17: ETTAPPAN D | D17: PRODUCTION | E17: BIAS CUTTING-5 | F17: 40634 | G17: =NOW()-F17 | H17: O | I17: U | J17: 10 | K17: 9 | L17: 8 | M17: 9 | O17: =SUM(J17:N17) | P17: =O17/IF(H17="L",20,IF(H17="U",30,IF(H17="O",40,IF(H17="I",20,"")))) | Q17: =IF(AND(H17="L", P17>=50%), "Pass", IF(AND(H17="U", P17>=60%), "Pass", IF(AND(H17="O", P17>=75%), "Pass", "Fail"))) | S17: 14 | T17: 11 | U17: =SUM(S17:T17) | V17: =U17/IF(H17="L",35,IF(H17="U",35,IF(H17="O",35,IF(H17="I",35,"")))) | W17: =IF(AND(H17="L", V17>=50%), "Pass", IF(AND(H17="U", V17>=60%), "Pass", IF(AND(H17="O", V17>=75%), "Pass", "Fail"))) | X17: =IF(AND(Q17="Pass", W17="Pass"), "Pass", "Fail") | Y17: =IF($X17="Pass",$H17, IF(H17="L","I", IF(H17="U","L", IF(H17="O","U", "I"))))
A18: =ROW()-2 | B18: 900132 | C18: KOMBAN M | D18: PRODUCTION | E18: BIAS CUTTING-4 | F18: 40634 | G18: =NOW()-F18 | H18: O | I18: U | J18: 9 | K18: 5 | L18: 7 | M18: 6 | O18: =SUM(J18:N18) | P18: =O18/IF(H18="L",20,IF(H18="U",30,IF(H18="O",40,IF(H18="I",20,"")))) | Q18: =IF(AND(H18="L", P18>=50%), "Pass", IF(AND(H18="U", P18>=60%), "Pass", IF(AND(H18="O", P18>=75%), "Pass", "Fail"))) | S18: 20 | T18: 15 | U18: =SUM(S18:T18) | V18: =U18/IF(H18="L",35,IF(H18="U",35,IF(H18="O",35,IF(H18="I",35,"")))) | W18: =IF(AND(H18="L", V18>=50%), "Pass", IF(AND(H18="U", V18>=60%), "Pass", IF(AND(H18="O", V18>=75%), "Pass", "Fail"))) | X18: =IF(AND(Q18="Pass", W18="Pass"), "Pass", "Fail") | Y18: =IF($X18="Pass",$H18, IF(H18="L","I", IF(H18="U","L", IF(H18="O","U", "I"))))
... A38: =ROW()-2 | B38: 900160 | C38: NALLA MADASAMY N | D38: PRODUCTION | E38: RADIAL MARANGONI | F38: 40634 | G38: =NOW()-F38 | H38: O | I38: O | J38: 9 | K38: 9 | L38: 9 | M38: 10 | O38: =SUM(J38:N38) | P38: =O38/IF(H38="L",20,IF(H38="U",30,IF(H38="O",40,IF(H38="I",20,"")))) | Q38: =IF(AND(H38="L", P38>=50%), "Pass", IF(AND(H38="U", P38>=60%), "Pass", IF(AND(H38="O", P38>=75%), "Pass", "Fail"))) | S38: 15 | T38: 12 | U38: =SUM(S38:T38) | V38: =U38/IF(H38="L",35,IF(H38="U",35,IF(H38="O",35,IF(H38="I",35,"")))) | W38: =IF(AND(H38="L", V38>=50%), "Pass", IF(AND(H38="U", V38>=60%), "Pass", IF(AND(H38="O", V38>=75%), "Pass", "Fail"))) | X38: =IF(AND(Q38="Pass", W38="Pass"), "Pass", "Fail") | Y38: =IF($X38="Pass",$H38, IF(H38="L","I", IF(H38="U","L", IF(H38="O","U", "I"))))
A39: =ROW()-2 | B39: 900161 | C39: MASANAM P | D39: PRODUCTION | E39: MIXING | F39: 40634 | G39: =NOW()-F39 | H39: O | I39: U | J39: NIL | P39: =O39/IF(H39="L",20,IF(H39="U",30,IF(H39="O",40,IF(H39="I",20,"")))) | Q39: =IF(AND(H39="L", P39>=50%), "Pass", IF(AND(H39="U", P39>=60%), "Pass", IF(AND(H39="O", P39>=75%), "Pass", "Fail"))) | S39: 14 | T39: 11 | U39: =SUM(S39:T39) | V39: =U39/IF(H39="L",35,IF(H39="U",35,IF(H39="O",35,IF(H39="I",35,"")))) | W39: =IF(AND(H39="L", V39>=50%), "Pass", IF(AND(H39="U", V39>=60%), "Pass", IF(AND(H39="O", V39>=75%), "Pass", "Fail"))) | X39: =IF(AND(Q39="Pass", W39="Pass"), "Pass", "Fail") | Y39: =IF($X39="Pass",$H39, IF(H39="L","I", IF(H39="U","L", IF(H39="O","U", "I"))))
A40: =ROW()-2 | B40: 900162 | C40: THIRUNAVUKKARASU A | D40: PRODUCTION | E40: MIXING | F40: 40634 | G40: =NOW()-F40 | H40: O | I40: U | J40: NIL | P40: =O40/IF(H40="L",20,IF(H40="U",30,IF(H40="O",40,IF(H40="I",20,"")))) | Q40: =IF(AND(H40="L", P40>=50%), "Pass", IF(AND(H40="U", P40>=60%), "Pass", IF(AND(H40="O", P40>=75%), "Pass", "Fail"))) | S40: 16 | T40: 12 | U40: =SUM(S40:T40) | V40: =U40/IF(H40="L",35,IF(H40="U",35,IF(H40="O",35,IF(H40="I",35,"")))) | W40: =IF(AND(H40="L", V40>=50%), "Pass", IF(AND(H40="U", V40>=60%), "Pass", IF(AND(H40="O", V40>=75%), "Pass", "Fail"))) | X40: =IF(AND(Q40="Pass", W40="Pass"), "Pass", "Fail") | Y40: =IF($X40="Pass",$H40, IF(H40="L","I", IF(H40="U","L", IF(H40="O","U", "I"))))
A41: =ROW()-2 | B41: 900163 | C41: NARAYANAN A | D41: PRODUCTION | E41: MIXING | F41: 40634 | G41: =NOW()-F41 | H41: O | I41: U | J41: NIL | P41: =O41/IF(H41="L",20,IF(H41="U",30,IF(H41="O",40,IF(H41="I",20,"")))) | Q41: =IF(AND(H41="L", P41>=50%), "Pass", IF(AND(H41="U", P41>=60%), "Pass", IF(AND(H41="O", P41>=75%), "Pass", "Fail"))) | S41: 15 | T41: 12 | U41: =SUM(S41:T41) | V41: =U41/IF(H41="L",35,IF(H41="U",35,IF(H41="O",35,IF(H41="I",35,"")))) | W41: =IF(AND(H41="L", V41>=50%), "Pass", IF(AND(H41="U", V41>=60%), "Pass", IF(AND(H41="O", V41>=75%), "Pass", "Fail"))) | X41: =IF(AND(Q41="Pass", W41="Pass"), "Pass", "Fail") | Y41: =IF($X41="Pass",$H41, IF(H41="L","I", IF(H41="U","L", IF(H41="O","U", "I"))))
A42: =ROW()-2 | B42: 900164 | C42: RAMESH T | D42: PRODUCTION | E42: MIXING | F42: 40634 | G42: =NOW()-F42 | H42: O | I42: U | J42: NIL | P42: =O42/IF(H42="L",20,IF(H42="U",30,IF(H42="O",40,IF(H42="I",20,"")))) | Q42: =IF(AND(H42="L", P42>=50%), "Pass", IF(AND(H42="U", P42>=60%), "Pass", IF(AND(H42="O", P42>=75%), "Pass", "Fail"))) | S42: 15 | T42: 11 | U42: =SUM(S42:T42) | V42: =U42/IF(H42="L",35,IF(H42="U",35,IF(H42="O",35,IF(H42="I",35,"")))) | W42: =IF(AND(H42="L", V42>=50%), "Pass", IF(AND(H42="U", V42>=60%), "Pass", IF(AND(H42="O", V42>=75%), "Pass", "Fail"))) | X42: =IF(AND(Q42="Pass", W42="Pass"), "Pass", "Fail") | Y42: =IF($X42="Pass",$H42, IF(H42="L","I", IF(H42="U","L", IF(H42="O","U", "I"))))
A43: =ROW()-2 | B43: 900165 | C43: MUTHU KUMAR G | D43: PRODUCTION | E43: 3 ROLL-P2 | F43: 40634 | G43: =NOW()-F43 | H43: O | I43: U | J43: 8 | K43: 5 | L43: 6 | M43: 8 | O43: =SUM(J43:N43) | P43: =O43/IF(H43="L",20,IF(H43="U",30,IF(H43="O",40,IF(H43="I",20,"")))) | Q43: =IF(AND(H43="L", P43>=50%), "Pass", IF(AND(H43="U", P43>=60%), "Pass", IF(AND(H43="O", P43>=75%), "Pass", "Fail"))) | S43: 15 | T43: 6 | U43: =SUM(S43:T43) | V43: =U43/IF(H43="L",35,IF(H43="U",35,IF(H43="O",35,IF(H43="I",35,"")))) | W43: =IF(AND(H43="L", V43>=50%), "Pass", IF(AND(H43="U", V43>=60%), "Pass", IF(AND(H43="O", V43>=75%), "Pass", "Fail"))) | X43: =IF(AND(Q43="Pass", W43="Pass"), "Pass", "Fail") | Y43: =IF($X43="Pass",$H43, IF(H43="L","I", IF(H43="U","L", IF(H43="O","U", "I"))))
A44: =ROW()-2 | B44: 900166 | C44: RAMESH V | D44: PRODUCTION | E44: MIXING | F44: 40634 | G44: =NOW()-F44 | H44: O | I44: U | J44: NIL | P44: =O44/IF(H44="L",20,IF(H44="U",30,IF(H44="O",40,IF(H44="I",20,"")))) | Q44: =IF(AND(H44="L", P44>=50%), "Pass", IF(AND(H44="U", P44>=60%), "Pass", IF(AND(H44="O", P44>=75%), "Pass", "Fail"))) | S44: 14 | T44: 12 | U44: =SUM(S44:T44) | V44: =U44/IF(H44="L",35,IF(H44="U",35,IF(H44="O",35,IF(H44="I",35,"")))) | W44: =IF(AND(H44="L", V44>=50%), "Pass", IF(AND(H44="U", V44>=60%), "Pass", IF(AND(H44="O", V44>=75%), "Pass", "Fail"))) | X44: =IF(AND(Q44="Pass", W44="Pass"), "Pass", "Fail") | Y44: =IF($X44="Pass",$H44, IF(H44="L","I", IF(H44="U","L", IF(H44="O","U", "I"))))
A45: =ROW()-2 | B45: 900167 | C45: PARAMASIVAN M | D45: PRODUCTION | E45: MIXING | F45: 40634 | G45: =NOW()-F45 | H45: O | I45: U | J45: NIL | P45: =O45/IF(H45="L",20,IF(H45="U",30,IF(H45="O",40,IF(H45="I",20,"")))) | Q45: =IF(AND(H45="L", P45>=50%), "Pass", IF(AND(H45="U", P45>=60%), "Pass", IF(AND(H45="O", P45>=75%), "Pass", "Fail"))) | S45: 15 | T45: 10 | U45: =SUM(S45:T45) | V45: =U45/IF(H45="L",35,IF(H45="U",35,IF(H45="O",35,IF(H45="I",35,"")))) | W45: =IF(AND(H45="L", V45>=50%), "Pass", IF(AND(H45="U", V45>=60%), "Pass", IF(AND(H45="O", V45>=75%), "Pass", "Fail"))) | X45: =IF(AND(Q45="Pass", W45="Pass"), "Pass", "Fail") | Y45: =IF($X45="Pass",$H45, IF(H45="L","I", IF(H45="U","L", IF(H45="O","U", "I"))))
A46: =ROW()-2 | B46: 900168 | C46: UGI SAMUEL Y | D46: PRODUCTION | E46: MIXING | F46: 40634 | G46: =NOW()-F46 | H46: O | I46: O | J46: NIL | P46: =O46/IF(H46="L",20,IF(H46="U",30,IF(H46="O",40,IF(H46="I",20,"")))) | Q46: =IF(AND(H46="L", P46>=50%), "Pass", IF(AND(H46="U", P46>=60%), "Pass", IF(AND(H46="O", P46>=75%), "Pass", "Fail"))) | S46: 16 | T46: 12 | U46: =SUM(S46:T46) | V46: =U46/IF(H46="L",35,IF(H46="U",35,IF(H46="O",35,IF(H46="I",35,"")))) | W46: =IF(AND(H46="L", V46>=50%), "Pass", IF(AND(H46="U", V46>=60%), "Pass", IF(AND(H46="O", V46>=75%), "Pass", "Fail"))) | X46: =IF(AND(Q46="Pass", W46="Pass"), "Pass", "Fail") | Y46: =IF($X46="Pass",$H46, IF(H46="L","I", IF(H46="U","L", IF(H46="O","U", "I"))))
A47: =ROW()-2 | B47: 900169 | C47: MARIAPPAN P | D47: PRODUCTION | E47: MIXING | F47: 40634 | G47: =NOW()-F47 | H47: O | I47: U | J47: NIL | P47: =O47/IF(H47="L",20,IF(H47="U",30,IF(H47="O",40,IF(H47="I",20,"")))) | Q47: =IF(AND(H47="L", P47>=50%), "Pass", IF(AND(H47="U", P47>=60%), "Pass", IF(AND(H47="O", P47>=75%), "Pass", "Fail"))) | S47: 16 | T47: 10 | U47: =SUM(S47:T47) | V47: =U47/IF(H47="L",35,IF(H47="U",35,IF(H47="O",35,IF(H47="I",35,"")))) | W47: =IF(AND(H47="L", V47>=50%), "Pass", IF(AND(H47="U", V47>=60%), "Pass", IF(AND(H47="O", V47>=75%), "Pass", "Fail"))) | X47: =IF(AND(Q47="Pass", W47="Pass"), "Pass", "Fail") | Y47: =IF($X47="Pass",$H47, IF(H47="L","I", IF(H47="U","L", IF(H47="O","U", "I"))))
A48: =ROW()-2 | B48: 900170 | C48: PERUMAL KRISHNAN S | D48: PRODUCTION | E48: MIXING | F48: 40634 | G48: =NOW()-F48 | H48: O | I48: U | J48: NIL | P48: =O48/IF(H48="L",20,IF(H48="U",30,IF(H48="O",40,IF(H48="I",20,"")))) | Q48: =IF(AND(H48="L", P48>=50%), "Pass", IF(AND(H48="U", P48>=60%), "Pass", IF(AND(H48="O", P48>=75%), "Pass", "Fail"))) | S48: 14 | T48: 11 | U48: =SUM(S48:T48) | V48: =U48/IF(H48="L",35,IF(H48="U",35,IF(H48="O",35,IF(H48="I",35,"")))) | W48: =IF(AND(H48="L", V48>=50%), "Pass", IF(AND(H48="U", V48>=60%), "Pass", IF(AND(H48="O", V48>=75%), "Pass", "Fail"))) | X48: =IF(AND(Q48="Pass", W48="Pass"), "Pass", "Fail") | Y48: =IF($X48="Pass",$H48, IF(H48="L","I", IF(H48="U","L", IF(H48="O","U", "I"))))
A49: =ROW()-2 | B49: 900171 | C49: JEYA KUMAR A | D49: PRODUCTION | E49: MIXING | F49: 40634 | G49: =NOW()-F49 | H49: O | I49: U | J49: NIL | P49: =O49/IF(H49="L",20,IF(H49="U",30,IF(H49="O",40,IF(H49="I",20,"")))) | Q49: =IF(AND(H49="L", P49>=50%), "Pass", IF(AND(H49="U", P49>=60%), "Pass", IF(AND(H49="O", P49>=75%), "Pass", "Fail"))) | S49: 14 | T49: 12 | U49: =SUM(S49:T49) | V49: =U49/IF(H49="L",35,IF(H49="U",35,IF(H49="O",35,IF(H49="I",35,"")))) | W49: =IF(AND(H49="L", V49>=50%), "Pass", IF(AND(H49="U", V49>=60%), "Pass", IF(AND(H49="O", V49>=75%), "Pass", "Fail"))) | X49: =IF(AND(Q49="Pass", W49="Pass"), "Pass", "Fail") | Y49: =IF($X49="Pass",$H49, IF(H49="L","I", IF(H49="U","L", IF(H49="O","U", "I"))))
A50: =ROW()-2 | B50: 900172 | C50: KANAGARAJ K | D50: PRODUCTION | E50: MIXING | F50: 40634 | G50: =NOW()-F50 | H50: O | I50: U | J50: NIL | P50: =O50/IF(H50="L",20,IF(H50="U",30,IF(H50="O",40,IF(H50="I",20,"")))) | Q50: =IF(AND(H50="L", P50>=50%), "Pass", IF(AND(H50="U", P50>=60%), "Pass", IF(AND(H50="O", P50>=75%), "Pass", "Fail"))) | S50: 16 | T50: 10 | U50: =SUM(S50:T50) | V50: =U50/IF(H50="L",35,IF(H50="U",35,IF(H50="O",35,IF(H50="I",35,"")))) | W50: =IF(AND(H50="L", V50>=50%), "Pass", IF(AND(H50="U", V50>=60%), "Pass", IF(AND(H50="O", V50>=75%), "Pass", "Fail"))) | X50: =IF(AND(Q50="Pass", W50="Pass"), "Pass", "Fail") | Y50: =IF($X50="Pass",$H50, IF(H50="L","I", IF(H50="U","L", IF(H50="O","U", "I"))))
A51: =ROW()-2 | B51: 900174 | C51: SANJAY KUMAR | D51: PRODUCTION | E51: MIXING | F51: 40634 | G51: =NOW()-F51 | H51: O | I51: U | J51: NIL | P51: =O51/IF(H51="L",20,IF(H51="U",30,IF(H51="O",40,IF(H51="I",20,"")))) | Q51: =IF(AND(H51="L", P51>=50%), "Pass", IF(AND(H51="U", P51>=60%), "Pass", IF(AND(H51="O", P51>=75%), "Pass", "Fail"))) | S51: 15 | T51: 11 | U51: =SUM(S51:T51) | V51: =U51/IF(H51="L",35,IF(H51="U",35,IF(H51="O",35,IF(H51="I",35,"")))) | W51: =IF(AND(H51="L", V51>=50%), "Pass", IF(AND(H51="U", V51>=60%), "Pass", IF(AND(H51="O", V51>=75%), "Pass", "Fail"))) | X51: =IF(AND(Q51="Pass", W51="Pass"), "Pass", "Fail") | Y51: =IF($X51="Pass",$H51, IF(H51="L","I", IF(H51="U","L", IF(H51="O","U", "I"))))
A52: =ROW()-2 | B52: 900175 | C52: RAJENDRA RAI | D52: PRODUCTION | E52: MIXING | F52: 40634 | G52: =NOW()-F52 | H52: O | I52: U | J52: NIL | P52: =O52/IF(H52="L",20,IF(H52="U",30,IF(H52="O",40,IF(H52="I",20,"")))) | Q52: =IF(AND(H52="L", P52>=50%), "Pass", IF(AND(H52="U", P52>=60%), "Pass", IF(AND(H52="O", P52>=75%), "Pass", "Fail"))) | S52: 16 | T52: 10 | U52: =SUM(S52:T52) | V52: =U52/IF(H52="L",35,IF(H52="U",35,IF(H52="O",35,IF(H52="I",35,"")))) | W52: =IF(AND(H52="L", V52>=50%), "Pass", IF(AND(H52="U", V52>=60%), "Pass", IF(AND(H52="O", V52>=75%), "Pass", "Fail"))) | X52: =IF(AND(Q52="Pass", W52="Pass"), "Pass", "Fail") | Y52: =IF($X52="Pass",$H52, IF(H52="L","I", IF(H52="U","L", IF(H52="O","U", "I"))))
A53: =ROW()-2 | B53: 900176 | C53: MUTHU RAJ G | D53: PRODUCTION | E53: MIXING | F53: 40634 | G53: =NOW()-F53 | H53: O | I53: O | J53: NIL | P53: =O53/IF(H53="L",20,IF(H53="U",30,IF(H53="O",40,IF(H53="I",20,"")))) | Q53: =IF(AND(H53="L", P53>=50%), "Pass", IF(AND(H53="U", P53>=60%), "Pass", IF(AND(H53="O", P53>=75%), "Pass", "Fail"))) | S53: 15 | T53: 12 | U53: =SUM(S53:T53) | V53: =U53/IF(H53="L",35,IF(H53="U",35,IF(H53="O",35,IF(H53="I",35,"")))) | W53: =IF(AND(H53="L", V53>=50%), "Pass", IF(AND(H53="U", V53>=60%), "Pass", IF(AND(H53="O", V53>=75%), "Pass", "Fail"))) | X53: =IF(AND(Q53="Pass", W53="Pass"), "Pass", "Fail") | Y53: =IF($X53="Pass",$H53, IF(H53="L","I", IF(H53="U","L", IF(H53="O","U", "I"))))
A54: =ROW()-2 | B54: 900177 | C54: DEEPAK KUMAR JENA N | D54: PRODUCTION | E54: MIXING | F54: 40634 | G54: =NOW()-F54 | H54: O | I54: U | J54: NIL | P54: =O54/IF(H54="L",20,IF(H54="U",30,IF(H54="O",40,IF(H54="I",20,"")))) | Q54: =IF(AND(H54="L", P54>=50%), "Pass", IF(AND(H54="U", P54>=60%), "Pass", IF(AND(H54="O", P54>=75%), "Pass", "Fail"))) | S54: 13 | T54: 11 | U54: =SUM(S54:T54) | V54: =U54/IF(H54="L",35,IF(H54="U",35,IF(H54="O",35,IF(H54="I",35,"")))) | W54: =IF(AND(H54="L", V54>=50%), "Pass", IF(AND(H54="U", V54>=60%), "Pass", IF(AND(H54="O", V54>=75%), "Pass", "Fail"))) | X54: =IF(AND(Q54="Pass", W54="Pass"), "Pass", "Fail") | Y54: =IF($X54="Pass",$H54, IF(H54="L","I", IF(H54="U","L", IF(H54="O","U", "I"))))
A55: =ROW()-2 | B55: 900178 | C55: MARI MUTHU S | D55: PRODUCTION | E55: TYRE BUILDING-P1 | F55: 40634 | G55: =NOW()-F55 | H55: O | I55: O | J55: 8 | K55: 9 | L55: 9 | M55: 9 | O55: =SUM(J55:N55) | P55: =O55/IF(H55="L",20,IF(H55="U",30,IF(H55="O",40,IF(H55="I",20,"")))) | Q55: =IF(AND(H55="L", P55>=50%), "Pass", IF(AND(H55="U", P55>=60%), "Pass", IF(AND(H55="O", P55>=75%), "Pass", "Fail"))) | S55: 17 | T55: 15 | U55: =SUM(S55:T55) | V55: =U55/IF(H55="L",35,IF(H55="U",35,IF(H55="O",35,IF(H55="I",35,"")))) | W55: =IF(AND(H55="L", V55>=50%), "Pass", IF(AND(H55="U", V55>=60%), "Pass", IF(AND(H55="O", V55>=75%), "Pass", "Fail"))) | X55: =IF(AND(Q55="Pass", W55="Pass"), "Pass", "Fail") | Y55: =IF($X55="Pass",$H55, IF(H55="L","I", IF(H55="U","L", IF(H55="O","U", "I"))))
A56: =ROW()-2 | B56: 900179 | C56: ELANGAMANI K | D56: PRODUCTION | E56: TYRE BUILDING-P2 | F56: 40634 | G56: =NOW()-F56 | H56: O | I56: O | J56: 9 | K56: 10 | L56: 6 | M56: 8 | O56: =SUM(J56:N56) | P56: =O56/IF(H56="L",20,IF(H56="U",30,IF(H56="O",40,IF(H56="I",20,"")))) | Q56: =IF(AND(H56="L", P56>=50%), "Pass", IF(AND(H56="U", P56>=60%), "Pass", IF(AND(H56="O", P56>=75%), "Pass", "Fail"))) | S56: 14 | T56: 11 | U56: =SUM(S56:T56) | V56: =U56/IF(H56="L",35,IF(H56="U",35,IF(H56="O",35,IF(H56="I",35,"")))) | W56: =IF(AND(H56="L", V56>=50%), "Pass", IF(AND(H56="U", V56>=60%), "Pass", IF(AND(H56="O", V56>=75%), "Pass", "Fail"))) | X56: =IF(AND(Q56="Pass", W56="Pass"), "Pass", "Fail") | Y56: =IF($X56="Pass",$H56, IF(H56="L","I", IF(H56="U","L", IF(H56="O","U", "I"))))
A57: =ROW()-2 | B57: 900180 | C57: MUTHU KANI S | D57: PRODUCTION | E57: TYRE BUILDING-P1 | F57: 40634 | G57: =NOW()-F57 | H57: O | I57: O | J57: 10 | K57: 10 | L57: 8 | M57: 8 | O57: =SUM(J57:N57) | P57: =O57/IF(H57="L",20,IF(H57="U",30,IF(H57="O",40,IF(H57="I",20,"")))) | Q57: =IF(AND(H57="L", P57>=50%), "Pass", IF(AND(H57="U", P57>=60%), "Pass", IF(AND(H57="O", P57>=75%), "Pass", "Fail"))) | S57: 15 | T57: 15 | U57: =SUM(S57:T57) | V57: =U57/IF(H57="L",35,IF(H57="U",35,IF(H57="O",35,IF(H57="I",35,"")))) | W57: =IF(AND(H57="L", V57>=50%), "Pass", IF(AND(H57="U", V57>=60%), "Pass", IF(AND(H57="O", V57>=75%), "Pass", "Fail"))) | X57: =IF(AND(Q57="Pass", W57="Pass"), "Pass", "Fail") | Y57: =IF($X57="Pass",$H57, IF(H57="L","I", IF(H57="U","L", IF(H57="O","U", "I"))))
A58: =ROW()-2 | B58: 900181 | C58: VALATHI RAJAN V | D58: PRODUCTION | E58: TYRE BUILDING-P2 | F58: 40634 | G58: =NOW()-F58 | H58: O | I58: O | J58: 8 | K58: 10 | L58: 7 | M58: 6 | O58: =SUM(J58:N58) | P58: =O58/IF(H58="L",20,IF(H58="U",30,IF(H58="O",40,IF(H58="I",20,"")))) | Q58: =IF(AND(H58="L", P58>=50%), "Pass", IF(AND(H58="U", P58>=60%), "Pass", IF(AND(H58="O", P58>=75%), "Pass", "Fail"))) | S58: 14 | T58: 10 | U58: =SUM(S58:T58) | V58: =U58/IF(H58="L",35,IF(H58="U",35,IF(H58="O",35,IF(H58="I",35,"")))) | W58: =IF(AND(H58="L", V58>=50%), "Pass", IF(AND(H58="U", V58>=60%), "Pass", IF(AND(H58="O", V58>=75%), "Pass", "Fail"))) | X58: =IF(AND(Q58="Pass", W58="Pass"), "Pass", "Fail") | Y58: =IF($X58="Pass",$H58, IF(H58="L","I", IF(H58="U","L", IF(H58="O","U", "I"))))
A59: =ROW()-2 | B59: 900182 | C59: PITCHIAH R | D59: PRODUCTION | E59: TYRE BUILDING-P1 | F59: 40634 | G59: =NOW()-F59 | H59: O | I59: O | J59: 10 | K59: 10 | L59: 8 | M59: 9 | O59: =SUM(J59:N59) | P59: =O59/IF(H59="L",20,IF(H59="U",30,IF(H59="O",40,IF(H59="I",20,"")))) | Q59: =IF(AND(H59="L", P59>=50%), "Pass", IF(AND(H59="U", P59>=60%), "Pass", IF(AND(H59="O", P59>=75%), "Pass", "Fail"))) | S59: 16 | T59: 15 | U59: =SUM(S59:T59) | V59: =U59/IF(H59="L",35,IF(H59="U",35,IF(H59="O",35,IF(H59="I",35,"")))) | W59: =IF(AND(H59="L", V59>=50%), "Pass", IF(AND(H59="U", V59>=60%), "Pass", IF(AND(H59="O", V59>=75%), "Pass", "Fail"))) | X59: =IF(AND(Q59="Pass", W59="Pass"), "Pass", "Fail") | Y59: =IF($X59="Pass",$H59, IF(H59="L","I", IF(H59="U","L", IF(H59="O","U", "I"))))
...

Sheet Left
J1: Quest | S1: Gemba
A2: S.NO | B2: EMP NO | C2: NAME | D2: DEPT | E2: SECTION | F2: DOJ | G2: Exp | H2: Eligible skill level | I2: Current skill level 2025 | J2: Safety | K2: Process | L2: Quality | M2: CI & TPM | N2: System | O2: Knowledge Mark | P2: Knowledge % | Q2: Result | S2: Safety/ 5S | T2: SOP's/ WI CHECK | U2: Skill Assessment Mark | V2: Skill Assessment % | W2: Result | X2: Overall Result | Y2: After evaluation Skill level
A3: =ROW()-2 | B3: LN0242 | C3: MUTHU KUTTI A | D3: PRODUCTION | E3: TYRE CURING | F3: 45369 | G3: =NOW()-F3 | H3: U | I3: L | J3: 5 | K3: 4 | L3: 5 | M3: 5 | N3: 4 | O3: =SUM(J3:N3) | P3: =O3/IF(H3="L",20,IF(H3="U",30,IF(H3="O",40,IF(H3="I",20,"")))) | Q3: =IF(AND(H3="L", P3>=50%), "Pass", IF(AND(H3="U", P3>=60%), "Pass", IF(AND(H3="O", P3>=75%), "Pass", "Fail"))) | S3: 17 | T3: 13 | U3: =SUM(S3:T3) | V3: =U3/IF(H3="L",35,IF(H3="U",35,IF(H3="O",35,IF(H3="I",35,"")))) | W3: =IF(AND(H3="L", V3>=50%), "Pass", IF(AND(H3="U", V3>=60%), "Pass", IF(AND(H3="O", V3>=75%), "Pass", "Fail"))) | X3: =IF(AND(Q3="Pass", W3="Pass"), "Pass", "Fail") | Y3: =IF($X3="Pass",$H3, IF(H3="L","I", IF(H3="U","L", IF(H3="O","U", "I")))) | AA3: =VLOOKUP($B3,[1]Sheet1!$B:$B,1,0) | AB3: =VLOOKUP($B3,'[2]Left Employee Report'!$D$5:$D$277,1,0)
A4: =ROW()-2 | B4: AK0426 | C4: GOPI U | D4: PRODUCTION | E4: TYRE BUILDING-P2 | F4: 42493 | G4: =NOW()-F4 | H4: O | I4: U | O4: =SUM(J4:N4) | P4: =O4/IF(H4="L",20,IF(H4="U",30,IF(H4="O",40,IF(H4="I",20,"")))) | Q4: =IF(AND(H4="L", P4>=50%), "Pass", IF(AND(H4="U", P4>=60%), "Pass", IF(AND(H4="O", P4>=75%), "Pass", "Fail"))) | U4: =SUM(S4:T4) | V4: =U4/IF(H4="L",35,IF(H4="U",35,IF(H4="O",35,IF(H4="I",35,"")))) | W4: =IF(AND(H4="L", V4>=50%), "Pass", IF(AND(H4="U", V4>=60%), "Pass", IF(AND(H4="O", V4>=75%), "Pass", "Fail"))) | X4: =IF(AND(Q4="Pass", W4="Pass"), "Pass", "Fail") | Y4: =IF($X4="Pass",$H4, IF(H4="L","I", IF(H4="U","L", IF(H4="O","U", "I")))) | AA4: =VLOOKUP($B4,[1]Sheet1!$B:$B,1,0) | AB4: =VLOOKUP($B4,'[3]Left Employee Report'!$D:$D,1,0)
A5: =ROW()-2 | B5: AK0640 | C5: KARUPPASAMY P | D5: PRODUCTION | E5: TYRE CURING | F5: 41324 | G5: =NOW()-F5 | H5: O | I5: O | O5: =SUM(J5:N5) | P5: =O5/IF(H5="L",20,IF(H5="U",30,IF(H5="O",40,IF(H5="I",20,"")))) | Q5: =IF(AND(H5="L", P5>=50%), "Pass", IF(AND(H5="U", P5>=60%), "Pass", IF(AND(H5="O", P5>=75%), "Pass", "Fail"))) | U5: =SUM(S5:T5) | V5: =U5/IF(H5="L",35,IF(H5="U",35,IF(H5="O",35,IF(H5="I",35,"")))) | W5: =IF(AND(H5="L", V5>=50%), "Pass", IF(AND(H5="U", V5>=60%), "Pass", IF(AND(H5="O", V5>=75%), "Pass", "Fail"))) | X5: =IF(AND(Q5="Pass", W5="Pass"), "Pass", "Fail") | Y5: =IF($X5="Pass",$H5, IF(H5="L","I", IF(H5="U","L", IF(H5="O","U", "I")))) | AA5: =VLOOKUP($B5,[1]Sheet1!$B:$B,1,0) | AB5: =VLOOKUP($B5,'[3]Left Employee Report'!$D:$D,1,0)
A6: =ROW()-2 | B6: AK0696 | C6: SIMAN TAMILARASAN | D6: PRODUCTION | E6: TYRE BUILDING-P2 | F6: 43042 | G6: =NOW()-F6 | H6: O | I6: U | O6: =SUM(J6:N6) | P6: =O6/IF(H6="L",20,IF(H6="U",30,IF(H6="O",40,IF(H6="I",20,"")))) | Q6: =IF(AND(H6="L", P6>=50%), "Pass", IF(AND(H6="U", P6>=60%), "Pass", IF(AND(H6="O", P6>=75%), "Pass", "Fail"))) | U6: =SUM(S6:T6) | V6: =U6/IF(H6="L",35,IF(H6="U",35,IF(H6="O",35,IF(H6="I",35,"")))) | W6: =IF(AND(H6="L", V6>=50%), "Pass", IF(AND(H6="U", V6>=60%), "Pass", IF(AND(H6="O", V6>=75%), "Pass", "Fail"))) | X6: =IF(AND(Q6="Pass", W6="Pass"), "Pass", "Fail") | Y6: =IF($X6="Pass",$H6, IF(H6="L","I", IF(H6="U","L", IF(H6="O","U", "I")))) | AA6: =VLOOKUP($B6,[1]Sheet1!$B:$B,1,0) | AB6: =VLOOKUP($B6,'[3]Left Employee Report'!$D:$D,1,0)
A7: =ROW()-2 | B7: AK0736 | C7: RAMABALAN RAJA | D7: PRODUCTION | E7: TYRE CURING | F7: 43084 | G7: =NOW()-F7 | H7: O | I7: O | O7: =SUM(J7:N7) | P7: =O7/IF(H7="L",20,IF(H7="U",30,IF(H7="O",40,IF(H7="I",20,"")))) | Q7: =IF(AND(H7="L", P7>=50%), "Pass", IF(AND(H7="U", P7>=60%), "Pass", IF(AND(H7="O", P7>=75%), "Pass", "Fail"))) | U7: =SUM(S7:T7) | V7: =U7/IF(H7="L",35,IF(H7="U",35,IF(H7="O",35,IF(H7="I",35,"")))) | W7: =IF(AND(H7="L", V7>=50%), "Pass", IF(AND(H7="U", V7>=60%), "Pass", IF(AND(H7="O", V7>=75%), "Pass", "Fail"))) | X7: =IF(AND(Q7="Pass", W7="Pass"), "Pass", "Fail") | Y7: =IF($X7="Pass",$H7, IF(H7="L","I", IF(H7="U","L", IF(H7="O","U", "I")))) | AA7: =VLOOKUP($B7,[1]Sheet1!$B:$B,1,0) | AB7: =VLOOKUP($B7,'[3]Left Employee Report'!$D:$D,1,0)
A8: =ROW()-2 | B8: AK0739 | C8: VIGNESH VELU | D8: PRODUCTION | E8: TYRE CURING | F8: 43085 | G8: =NOW()-F8 | H8: O | I8: O | O8: =SUM(J8:N8) | P8: =O8/IF(H8="L",20,IF(H8="U",30,IF(H8="O",40,IF(H8="I",20,"")))) | Q8: =IF(AND(H8="L", P8>=50%), "Pass", IF(AND(H8="U", P8>=60%), "Pass", IF(AND(H8="O", P8>=75%), "Pass", "Fail"))) | U8: =SUM(S8:T8) | V8: =U8/IF(H8="L",35,IF(H8="U",35,IF(H8="O",35,IF(H8="I",35,"")))) | W8: =IF(AND(H8="L", V8>=50%), "Pass", IF(AND(H8="U", V8>=60%), "Pass", IF(AND(H8="O", V8>=75%), "Pass", "Fail"))) | X8: =IF(AND(Q8="Pass", W8="Pass"), "Pass", "Fail") | Y8: =IF($X8="Pass",$H8, IF(H8="L","I", IF(H8="U","L", IF(H8="O","U", "I")))) | AA8: =VLOOKUP($B8,[1]Sheet1!$B:$B,1,0) | AB8: =VLOOKUP($B8,'[3]Left Employee Report'!$D:$D,1,0)
A9: =ROW()-2 | B9: AK0810 | C9: DURAI MURUGAN R | D9: PRODUCTION | E9: BEAD WINDING | F9: 43288 | G9: =NOW()-F9 | H9: O | I9: U | O9: =SUM(J9:N9) | P9: =O9/IF(H9="L",20,IF(H9="U",30,IF(H9="O",40,IF(H9="I",20,"")))) | Q9: =IF(AND(H9="L", P9>=50%), "Pass", IF(AND(H9="U", P9>=60%), "Pass", IF(AND(H9="O", P9>=75%), "Pass", "Fail"))) | U9: =SUM(S9:T9) | V9: =U9/IF(H9="L",35,IF(H9="U",35,IF(H9="O",35,IF(H9="I",35,"")))) | W9: =IF(AND(H9="L", V9>=50%), "Pass", IF(AND(H9="U", V9>=60%), "Pass", IF(AND(H9="O", V9>=75%), "Pass", "Fail"))) | X9: =IF(AND(Q9="Pass", W9="Pass"), "Pass", "Fail") | Y9: =IF($X9="Pass",$H9, IF(H9="L","I", IF(H9="U","L", IF(H9="O","U", "I")))) | AA9: =VLOOKUP($B9,[1]Sheet1!$B:$B,1,0) | AB9: =VLOOKUP($B9,'[3]Left Employee Report'!$D:$D,1,0)
A10: =ROW()-2 | B10: AK0825 | C10: KARUPPASAMY P | D10: PRODUCTION | E10: TYRE CURING | F10: 43413 | G10: =NOW()-F10 | H10: O | I10: O | O10: =SUM(J10:N10) | P10: =O10/IF(H10="L",20,IF(H10="U",30,IF(H10="O",40,IF(H10="I",20,"")))) | Q10: =IF(AND(H10="L", P10>=50%), "Pass", IF(AND(H10="U", P10>=60%), "Pass", IF(AND(H10="O", P10>=75%), "Pass", "Fail"))) | U10: =SUM(S10:T10) | V10: =U10/IF(H10="L",35,IF(H10="U",35,IF(H10="O",35,IF(H10="I",35,"")))) | W10: =IF(AND(H10="L", V10>=50%), "Pass", IF(AND(H10="U", V10>=60%), "Pass", IF(AND(H10="O", V10>=75%), "Pass", "Fail"))) | X10: =IF(AND(Q10="Pass", W10="Pass"), "Pass", "Fail") | Y10: =IF($X10="Pass",$H10, IF(H10="L","I", IF(H10="U","L", IF(H10="O","U", "I")))) | AA10: =VLOOKUP($B10,[1]Sheet1!$B:$B,1,0) | AB10: =VLOOKUP($B10,'[3]Left Employee Report'!$D:$D,1,0)
A11: =ROW()-2 | B11: AK1178 | C11: VEYILU MUTHU | D11: PRODUCTION | E11: TYRE CURING | F11: 45678 | G11: =NOW()-F11 | H11: L | I11: L | O11: =SUM(J11:N11) | P11: =O11/IF(H11="L",20,IF(H11="U",30,IF(H11="O",40,IF(H11="I",20,"")))) | Q11: =IF(AND(H11="L", P11>=50%), "Pass", IF(AND(H11="U", P11>=60%), "Pass", IF(AND(H11="O", P11>=75%), "Pass", "Fail"))) | U11: =SUM(S11:T11) | V11: =U11/IF(H11="L",35,IF(H11="U",35,IF(H11="O",35,IF(H11="I",35,"")))) | W11: =IF(AND(H11="L", V11>=50%), "Pass", IF(AND(H11="U", V11>=60%), "Pass", IF(AND(H11="O", V11>=75%), "Pass", "Fail"))) | X11: =IF(AND(Q11="Pass", W11="Pass"), "Pass", "Fail") | Y11: =IF($X11="Pass",$H11, IF(H11="L","I", IF(H11="U","L", IF(H11="O","U", "I")))) | AA11: =VLOOKUP($B11,[1]Sheet1!$B:$B,1,0) | AB11: =VLOOKUP($B11,'[3]Left Employee Report'!$D:$D,1,0)
